[2023-07-17T11:06:32.252+0000] {processor.py:157} INFO - Started process (PID=49) to work on /home/airflow/.local/lib/python3.7/site-packages/airflow/example_dags/example_setup_teardown.py
[2023-07-17T11:06:32.253+0000] {processor.py:826} INFO - Processing file /home/airflow/.local/lib/python3.7/site-packages/airflow/example_dags/example_setup_teardown.py for tasks to queue
[2023-07-17T11:06:32.255+0000] {logging_mixin.py:150} INFO - [2023-07-17T11:06:32.254+0000] {dagbag.py:541} INFO - Filling up the DagBag from /home/airflow/.local/lib/python3.7/site-packages/airflow/example_dags/example_setup_teardown.py
[2023-07-17T11:06:32.261+0000] {processor.py:838} WARNING - No viable dags retrieved from /home/airflow/.local/lib/python3.7/site-packages/airflow/example_dags/example_setup_teardown.py
[2023-07-17T11:06:32.272+0000] {processor.py:182} ERROR - Got an exception! Propagating...
Traceback (most recent call last):
  File "/home/airflow/.local/lib/python3.7/site-packages/sqlalchemy/engine/base.py", line 3371, in _wrap_pool_connect
    return fn()
  File "/home/airflow/.local/lib/python3.7/site-packages/sqlalchemy/pool/base.py", line 327, in connect
    return _ConnectionFairy._checkout(self)
  File "/home/airflow/.local/lib/python3.7/site-packages/sqlalchemy/pool/base.py", line 894, in _checkout
    fairy = _ConnectionRecord.checkout(pool)
  File "/home/airflow/.local/lib/python3.7/site-packages/sqlalchemy/pool/base.py", line 493, in checkout
    rec = pool._do_get()
  File "/home/airflow/.local/lib/python3.7/site-packages/sqlalchemy/pool/impl.py", line 146, in _do_get
    self._dec_overflow()
  File "/home/airflow/.local/lib/python3.7/site-packages/sqlalchemy/util/langhelpers.py", line 72, in __exit__
    with_traceback=exc_tb,
  File "/home/airflow/.local/lib/python3.7/site-packages/sqlalchemy/util/compat.py", line 211, in raise_
    raise exception
  File "/home/airflow/.local/lib/python3.7/site-packages/sqlalchemy/pool/impl.py", line 143, in _do_get
    return self._create_connection()
  File "/home/airflow/.local/lib/python3.7/site-packages/sqlalchemy/pool/base.py", line 273, in _create_connection
    return _ConnectionRecord(self)
  File "/home/airflow/.local/lib/python3.7/site-packages/sqlalchemy/pool/base.py", line 388, in __init__
    self.__connect()
  File "/home/airflow/.local/lib/python3.7/site-packages/sqlalchemy/pool/base.py", line 691, in __connect
    pool.logger.debug("Error on connect(): %s", e)
  File "/home/airflow/.local/lib/python3.7/site-packages/sqlalchemy/util/langhelpers.py", line 72, in __exit__
    with_traceback=exc_tb,
  File "/home/airflow/.local/lib/python3.7/site-packages/sqlalchemy/util/compat.py", line 211, in raise_
    raise exception
  File "/home/airflow/.local/lib/python3.7/site-packages/sqlalchemy/pool/base.py", line 686, in __connect
    self.dbapi_connection = connection = pool._invoke_creator(self)
  File "/home/airflow/.local/lib/python3.7/site-packages/sqlalchemy/engine/create.py", line 574, in connect
    return dialect.connect(*cargs, **cparams)
  File "/home/airflow/.local/lib/python3.7/site-packages/sqlalchemy/engine/default.py", line 598, in connect
    return self.dbapi.connect(*cargs, **cparams)
  File "/home/airflow/.local/lib/python3.7/site-packages/psycopg2/__init__.py", line 122, in connect
    conn = _connect(dsn, connection_factory=connection_factory, **kwasync)
psycopg2.OperationalError: could not translate host name "postgres" to address: Temporary failure in name resolution


The above exception was the direct cause of the following exception:

Traceback (most recent call last):
  File "/home/airflow/.local/lib/python3.7/site-packages/airflow/dag_processing/processor.py", line 178, in _run_file_processor
    _handle_dag_file_processing()
  File "/home/airflow/.local/lib/python3.7/site-packages/airflow/dag_processing/processor.py", line 162, in _handle_dag_file_processing
    callback_requests=callback_requests,
  File "/home/airflow/.local/lib/python3.7/site-packages/airflow/utils/session.py", line 76, in wrapper
    return func(*args, session=session, **kwargs)
  File "/home/airflow/.local/lib/python3.7/site-packages/airflow/dag_processing/processor.py", line 842, in process_file
    session=session,
  File "/home/airflow/.local/lib/python3.7/site-packages/airflow/api_internal/internal_api_call.py", line 112, in wrapper
    return func(*args, **kwargs)
  File "/home/airflow/.local/lib/python3.7/site-packages/airflow/utils/session.py", line 73, in wrapper
    return func(*args, **kwargs)
  File "/home/airflow/.local/lib/python3.7/site-packages/airflow/dag_processing/processor.py", line 617, in update_import_errors
    ).delete(synchronize_session="fetch")
  File "/home/airflow/.local/lib/python3.7/site-packages/sqlalchemy/orm/query.py", line 3225, in delete
    execution_options={"synchronize_session": synchronize_session},
  File "/home/airflow/.local/lib/python3.7/site-packages/sqlalchemy/orm/session.py", line 1716, in execute
    conn = self._connection_for_bind(bind)
  File "/home/airflow/.local/lib/python3.7/site-packages/sqlalchemy/orm/session.py", line 1556, in _connection_for_bind
    engine, execution_options
  File "/home/airflow/.local/lib/python3.7/site-packages/sqlalchemy/orm/session.py", line 750, in _connection_for_bind
    conn = bind.connect()
  File "/home/airflow/.local/lib/python3.7/site-packages/sqlalchemy/engine/base.py", line 3325, in connect
    return self._connection_cls(self, close_with_result=close_with_result)
  File "/home/airflow/.local/lib/python3.7/site-packages/sqlalchemy/engine/base.py", line 96, in __init__
    else engine.raw_connection()
  File "/home/airflow/.local/lib/python3.7/site-packages/sqlalchemy/engine/base.py", line 3404, in raw_connection
    return self._wrap_pool_connect(self.pool.connect, _connection)
  File "/home/airflow/.local/lib/python3.7/site-packages/sqlalchemy/engine/base.py", line 3375, in _wrap_pool_connect
    e, dialect, self
  File "/home/airflow/.local/lib/python3.7/site-packages/sqlalchemy/engine/base.py", line 2209, in _handle_dbapi_exception_noconnection
    sqlalchemy_exception, with_traceback=exc_info[2], from_=e
  File "/home/airflow/.local/lib/python3.7/site-packages/sqlalchemy/util/compat.py", line 211, in raise_
    raise exception
  File "/home/airflow/.local/lib/python3.7/site-packages/sqlalchemy/engine/base.py", line 3371, in _wrap_pool_connect
    return fn()
  File "/home/airflow/.local/lib/python3.7/site-packages/sqlalchemy/pool/base.py", line 327, in connect
    return _ConnectionFairy._checkout(self)
  File "/home/airflow/.local/lib/python3.7/site-packages/sqlalchemy/pool/base.py", line 894, in _checkout
    fairy = _ConnectionRecord.checkout(pool)
  File "/home/airflow/.local/lib/python3.7/site-packages/sqlalchemy/pool/base.py", line 493, in checkout
    rec = pool._do_get()
  File "/home/airflow/.local/lib/python3.7/site-packages/sqlalchemy/pool/impl.py", line 146, in _do_get
    self._dec_overflow()
  File "/home/airflow/.local/lib/python3.7/site-packages/sqlalchemy/util/langhelpers.py", line 72, in __exit__
    with_traceback=exc_tb,
  File "/home/airflow/.local/lib/python3.7/site-packages/sqlalchemy/util/compat.py", line 211, in raise_
    raise exception
  File "/home/airflow/.local/lib/python3.7/site-packages/sqlalchemy/pool/impl.py", line 143, in _do_get
    return self._create_connection()
  File "/home/airflow/.local/lib/python3.7/site-packages/sqlalchemy/pool/base.py", line 273, in _create_connection
    return _ConnectionRecord(self)
  File "/home/airflow/.local/lib/python3.7/site-packages/sqlalchemy/pool/base.py", line 388, in __init__
    self.__connect()
  File "/home/airflow/.local/lib/python3.7/site-packages/sqlalchemy/pool/base.py", line 691, in __connect
    pool.logger.debug("Error on connect(): %s", e)
  File "/home/airflow/.local/lib/python3.7/site-packages/sqlalchemy/util/langhelpers.py", line 72, in __exit__
    with_traceback=exc_tb,
  File "/home/airflow/.local/lib/python3.7/site-packages/sqlalchemy/util/compat.py", line 211, in raise_
    raise exception
  File "/home/airflow/.local/lib/python3.7/site-packages/sqlalchemy/pool/base.py", line 686, in __connect
    self.dbapi_connection = connection = pool._invoke_creator(self)
  File "/home/airflow/.local/lib/python3.7/site-packages/sqlalchemy/engine/create.py", line 574, in connect
    return dialect.connect(*cargs, **cparams)
  File "/home/airflow/.local/lib/python3.7/site-packages/sqlalchemy/engine/default.py", line 598, in connect
    return self.dbapi.connect(*cargs, **cparams)
  File "/home/airflow/.local/lib/python3.7/site-packages/psycopg2/__init__.py", line 122, in connect
    conn = _connect(dsn, connection_factory=connection_factory, **kwasync)
sqlalchemy.exc.OperationalError: (psycopg2.OperationalError) could not translate host name "postgres" to address: Temporary failure in name resolution

(Background on this error at: https://sqlalche.me/e/14/e3q8)
[2023-07-17T11:07:30.982+0000] {processor.py:157} INFO - Started process (PID=39) to work on /home/airflow/.local/lib/python3.7/site-packages/airflow/example_dags/example_setup_teardown.py
[2023-07-17T11:07:30.986+0000] {processor.py:826} INFO - Processing file /home/airflow/.local/lib/python3.7/site-packages/airflow/example_dags/example_setup_teardown.py for tasks to queue
[2023-07-17T11:07:30.987+0000] {logging_mixin.py:150} INFO - [2023-07-17T11:07:30.987+0000] {dagbag.py:541} INFO - Filling up the DagBag from /home/airflow/.local/lib/python3.7/site-packages/airflow/example_dags/example_setup_teardown.py
[2023-07-17T11:07:30.990+0000] {processor.py:838} WARNING - No viable dags retrieved from /home/airflow/.local/lib/python3.7/site-packages/airflow/example_dags/example_setup_teardown.py
[2023-07-17T11:07:31.093+0000] {processor.py:179} INFO - Processing /home/airflow/.local/lib/python3.7/site-packages/airflow/example_dags/example_setup_teardown.py took 0.136 seconds
[2023-07-17T11:09:07.614+0000] {processor.py:157} INFO - Started process (PID=40) to work on /home/airflow/.local/lib/python3.7/site-packages/airflow/example_dags/example_setup_teardown.py
[2023-07-17T11:09:07.663+0000] {processor.py:826} INFO - Processing file /home/airflow/.local/lib/python3.7/site-packages/airflow/example_dags/example_setup_teardown.py for tasks to queue
[2023-07-17T11:09:07.694+0000] {logging_mixin.py:150} INFO - [2023-07-17T11:09:07.689+0000] {dagbag.py:541} INFO - Filling up the DagBag from /home/airflow/.local/lib/python3.7/site-packages/airflow/example_dags/example_setup_teardown.py
[2023-07-17T11:09:07.887+0000] {processor.py:838} WARNING - No viable dags retrieved from /home/airflow/.local/lib/python3.7/site-packages/airflow/example_dags/example_setup_teardown.py
[2023-07-17T11:09:14.825+0000] {processor.py:179} INFO - Processing /home/airflow/.local/lib/python3.7/site-packages/airflow/example_dags/example_setup_teardown.py took 7.233 seconds
