[2023-07-17T11:06:28.329+0000] {processor.py:157} INFO - Started process (PID=42) to work on /home/airflow/.local/lib/python3.7/site-packages/airflow/example_dags/example_latest_only.py
[2023-07-17T11:06:28.340+0000] {processor.py:826} INFO - Processing file /home/airflow/.local/lib/python3.7/site-packages/airflow/example_dags/example_latest_only.py for tasks to queue
[2023-07-17T11:06:28.344+0000] {logging_mixin.py:150} INFO - [2023-07-17T11:06:28.344+0000] {dagbag.py:541} INFO - Filling up the DagBag from /home/airflow/.local/lib/python3.7/site-packages/airflow/example_dags/example_latest_only.py
[2023-07-17T11:06:28.721+0000] {processor.py:836} INFO - DAG(s) dict_keys(['latest_only']) retrieved from /home/airflow/.local/lib/python3.7/site-packages/airflow/example_dags/example_latest_only.py
[2023-07-17T11:06:29.324+0000] {processor.py:182} ERROR - Got an exception! Propagating...
Traceback (most recent call last):
  File "/home/airflow/.local/lib/python3.7/site-packages/sqlalchemy/engine/base.py", line 3371, in _wrap_pool_connect
    return fn()
  File "/home/airflow/.local/lib/python3.7/site-packages/sqlalchemy/pool/base.py", line 327, in connect
    return _ConnectionFairy._checkout(self)
  File "/home/airflow/.local/lib/python3.7/site-packages/sqlalchemy/pool/base.py", line 894, in _checkout
    fairy = _ConnectionRecord.checkout(pool)
  File "/home/airflow/.local/lib/python3.7/site-packages/sqlalchemy/pool/base.py", line 493, in checkout
    rec = pool._do_get()
  File "/home/airflow/.local/lib/python3.7/site-packages/sqlalchemy/pool/impl.py", line 146, in _do_get
    self._dec_overflow()
  File "/home/airflow/.local/lib/python3.7/site-packages/sqlalchemy/util/langhelpers.py", line 72, in __exit__
    with_traceback=exc_tb,
  File "/home/airflow/.local/lib/python3.7/site-packages/sqlalchemy/util/compat.py", line 211, in raise_
    raise exception
  File "/home/airflow/.local/lib/python3.7/site-packages/sqlalchemy/pool/impl.py", line 143, in _do_get
    return self._create_connection()
  File "/home/airflow/.local/lib/python3.7/site-packages/sqlalchemy/pool/base.py", line 273, in _create_connection
    return _ConnectionRecord(self)
  File "/home/airflow/.local/lib/python3.7/site-packages/sqlalchemy/pool/base.py", line 388, in __init__
    self.__connect()
  File "/home/airflow/.local/lib/python3.7/site-packages/sqlalchemy/pool/base.py", line 691, in __connect
    pool.logger.debug("Error on connect(): %s", e)
  File "/home/airflow/.local/lib/python3.7/site-packages/sqlalchemy/util/langhelpers.py", line 72, in __exit__
    with_traceback=exc_tb,
  File "/home/airflow/.local/lib/python3.7/site-packages/sqlalchemy/util/compat.py", line 211, in raise_
    raise exception
  File "/home/airflow/.local/lib/python3.7/site-packages/sqlalchemy/pool/base.py", line 686, in __connect
    self.dbapi_connection = connection = pool._invoke_creator(self)
  File "/home/airflow/.local/lib/python3.7/site-packages/sqlalchemy/engine/create.py", line 574, in connect
    return dialect.connect(*cargs, **cparams)
  File "/home/airflow/.local/lib/python3.7/site-packages/sqlalchemy/engine/default.py", line 598, in connect
    return self.dbapi.connect(*cargs, **cparams)
  File "/home/airflow/.local/lib/python3.7/site-packages/psycopg2/__init__.py", line 122, in connect
    conn = _connect(dsn, connection_factory=connection_factory, **kwasync)
psycopg2.OperationalError: could not translate host name "postgres" to address: Temporary failure in name resolution


The above exception was the direct cause of the following exception:

Traceback (most recent call last):
  File "/home/airflow/.local/lib/python3.7/site-packages/airflow/dag_processing/processor.py", line 178, in _run_file_processor
    _handle_dag_file_processing()
  File "/home/airflow/.local/lib/python3.7/site-packages/airflow/dag_processing/processor.py", line 162, in _handle_dag_file_processing
    callback_requests=callback_requests,
  File "/home/airflow/.local/lib/python3.7/site-packages/airflow/utils/session.py", line 76, in wrapper
    return func(*args, session=session, **kwargs)
  File "/home/airflow/.local/lib/python3.7/site-packages/airflow/dag_processing/processor.py", line 857, in process_file
    pickle_dags=pickle_dags,
  File "/home/airflow/.local/lib/python3.7/site-packages/airflow/api_internal/internal_api_call.py", line 112, in wrapper
    return func(*args, **kwargs)
  File "/home/airflow/.local/lib/python3.7/site-packages/airflow/utils/session.py", line 76, in wrapper
    return func(*args, session=session, **kwargs)
  File "/home/airflow/.local/lib/python3.7/site-packages/airflow/dag_processing/processor.py", line 890, in save_dag_to_db
    import_errors = DagBag._sync_to_db(dags=dags, processor_subdir=dag_directory, session=session)
  File "/home/airflow/.local/lib/python3.7/site-packages/airflow/utils/session.py", line 73, in wrapper
    return func(*args, **kwargs)
  File "/home/airflow/.local/lib/python3.7/site-packages/airflow/models/dagbag.py", line 659, in _sync_to_db
    for attempt in run_with_db_retries(logger=log):
  File "/home/airflow/.local/lib/python3.7/site-packages/tenacity/__init__.py", line 347, in __iter__
    do = self.iter(retry_state=retry_state)
  File "/home/airflow/.local/lib/python3.7/site-packages/tenacity/__init__.py", line 325, in iter
    raise retry_exc.reraise()
  File "/home/airflow/.local/lib/python3.7/site-packages/tenacity/__init__.py", line 158, in reraise
    raise self.last_attempt.result()
  File "/usr/local/lib/python3.7/concurrent/futures/_base.py", line 428, in result
    return self.__get_result()
  File "/usr/local/lib/python3.7/concurrent/futures/_base.py", line 384, in __get_result
    raise self._exception
  File "/home/airflow/.local/lib/python3.7/site-packages/airflow/models/dagbag.py", line 671, in _sync_to_db
    serialize_errors.extend(_serialize_dag_capturing_errors(dag, session))
  File "/home/airflow/.local/lib/python3.7/site-packages/airflow/models/dagbag.py", line 641, in _serialize_dag_capturing_errors
    session=session,
  File "/home/airflow/.local/lib/python3.7/site-packages/airflow/utils/session.py", line 73, in wrapper
    return func(*args, **kwargs)
  File "/home/airflow/.local/lib/python3.7/site-packages/airflow/models/serialized_dag.py", line 149, in write_dag
    (timezone.utcnow() - timedelta(seconds=min_update_interval)) < cls.last_updated,
  File "/home/airflow/.local/lib/python3.7/site-packages/sqlalchemy/orm/query.py", line 2893, in scalar
    ret = self.one()
  File "/home/airflow/.local/lib/python3.7/site-packages/sqlalchemy/orm/query.py", line 2870, in one
    return self._iter().one()
  File "/home/airflow/.local/lib/python3.7/site-packages/sqlalchemy/orm/query.py", line 2919, in _iter
    execution_options={"_sa_orm_load_options": self.load_options},
  File "/home/airflow/.local/lib/python3.7/site-packages/sqlalchemy/orm/session.py", line 1716, in execute
    conn = self._connection_for_bind(bind)
  File "/home/airflow/.local/lib/python3.7/site-packages/sqlalchemy/orm/session.py", line 1556, in _connection_for_bind
    engine, execution_options
  File "/home/airflow/.local/lib/python3.7/site-packages/sqlalchemy/orm/session.py", line 750, in _connection_for_bind
    conn = bind.connect()
  File "/home/airflow/.local/lib/python3.7/site-packages/sqlalchemy/engine/base.py", line 3325, in connect
    return self._connection_cls(self, close_with_result=close_with_result)
  File "/home/airflow/.local/lib/python3.7/site-packages/sqlalchemy/engine/base.py", line 96, in __init__
    else engine.raw_connection()
  File "/home/airflow/.local/lib/python3.7/site-packages/sqlalchemy/engine/base.py", line 3404, in raw_connection
    return self._wrap_pool_connect(self.pool.connect, _connection)
  File "/home/airflow/.local/lib/python3.7/site-packages/sqlalchemy/engine/base.py", line 3375, in _wrap_pool_connect
    e, dialect, self
  File "/home/airflow/.local/lib/python3.7/site-packages/sqlalchemy/engine/base.py", line 2209, in _handle_dbapi_exception_noconnection
    sqlalchemy_exception, with_traceback=exc_info[2], from_=e
  File "/home/airflow/.local/lib/python3.7/site-packages/sqlalchemy/util/compat.py", line 211, in raise_
    raise exception
  File "/home/airflow/.local/lib/python3.7/site-packages/sqlalchemy/engine/base.py", line 3371, in _wrap_pool_connect
    return fn()
  File "/home/airflow/.local/lib/python3.7/site-packages/sqlalchemy/pool/base.py", line 327, in connect
    return _ConnectionFairy._checkout(self)
  File "/home/airflow/.local/lib/python3.7/site-packages/sqlalchemy/pool/base.py", line 894, in _checkout
    fairy = _ConnectionRecord.checkout(pool)
  File "/home/airflow/.local/lib/python3.7/site-packages/sqlalchemy/pool/base.py", line 493, in checkout
    rec = pool._do_get()
  File "/home/airflow/.local/lib/python3.7/site-packages/sqlalchemy/pool/impl.py", line 146, in _do_get
    self._dec_overflow()
  File "/home/airflow/.local/lib/python3.7/site-packages/sqlalchemy/util/langhelpers.py", line 72, in __exit__
    with_traceback=exc_tb,
  File "/home/airflow/.local/lib/python3.7/site-packages/sqlalchemy/util/compat.py", line 211, in raise_
    raise exception
  File "/home/airflow/.local/lib/python3.7/site-packages/sqlalchemy/pool/impl.py", line 143, in _do_get
    return self._create_connection()
  File "/home/airflow/.local/lib/python3.7/site-packages/sqlalchemy/pool/base.py", line 273, in _create_connection
    return _ConnectionRecord(self)
  File "/home/airflow/.local/lib/python3.7/site-packages/sqlalchemy/pool/base.py", line 388, in __init__
    self.__connect()
  File "/home/airflow/.local/lib/python3.7/site-packages/sqlalchemy/pool/base.py", line 691, in __connect
    pool.logger.debug("Error on connect(): %s", e)
  File "/home/airflow/.local/lib/python3.7/site-packages/sqlalchemy/util/langhelpers.py", line 72, in __exit__
    with_traceback=exc_tb,
  File "/home/airflow/.local/lib/python3.7/site-packages/sqlalchemy/util/compat.py", line 211, in raise_
    raise exception
  File "/home/airflow/.local/lib/python3.7/site-packages/sqlalchemy/pool/base.py", line 686, in __connect
    self.dbapi_connection = connection = pool._invoke_creator(self)
  File "/home/airflow/.local/lib/python3.7/site-packages/sqlalchemy/engine/create.py", line 574, in connect
    return dialect.connect(*cargs, **cparams)
  File "/home/airflow/.local/lib/python3.7/site-packages/sqlalchemy/engine/default.py", line 598, in connect
    return self.dbapi.connect(*cargs, **cparams)
  File "/home/airflow/.local/lib/python3.7/site-packages/psycopg2/__init__.py", line 122, in connect
    conn = _connect(dsn, connection_factory=connection_factory, **kwasync)
sqlalchemy.exc.OperationalError: (psycopg2.OperationalError) could not translate host name "postgres" to address: Temporary failure in name resolution

(Background on this error at: https://sqlalche.me/e/14/e3q8)
[2023-07-17T11:07:26.804+0000] {processor.py:157} INFO - Started process (PID=32) to work on /home/airflow/.local/lib/python3.7/site-packages/airflow/example_dags/example_latest_only.py
[2023-07-17T11:07:26.805+0000] {processor.py:826} INFO - Processing file /home/airflow/.local/lib/python3.7/site-packages/airflow/example_dags/example_latest_only.py for tasks to queue
[2023-07-17T11:07:26.806+0000] {logging_mixin.py:150} INFO - [2023-07-17T11:07:26.806+0000] {dagbag.py:541} INFO - Filling up the DagBag from /home/airflow/.local/lib/python3.7/site-packages/airflow/example_dags/example_latest_only.py
[2023-07-17T11:07:26.829+0000] {processor.py:836} INFO - DAG(s) dict_keys(['latest_only']) retrieved from /home/airflow/.local/lib/python3.7/site-packages/airflow/example_dags/example_latest_only.py
[2023-07-17T11:07:27.366+0000] {logging_mixin.py:150} INFO - [2023-07-17T11:07:27.365+0000] {manager.py:504} INFO - Created Permission View: can delete on DAG:latest_only
[2023-07-17T11:07:27.385+0000] {logging_mixin.py:150} INFO - [2023-07-17T11:07:27.384+0000] {manager.py:504} INFO - Created Permission View: can edit on DAG:latest_only
[2023-07-17T11:07:27.392+0000] {logging_mixin.py:150} INFO - [2023-07-17T11:07:27.392+0000] {manager.py:504} INFO - Created Permission View: can read on DAG:latest_only
[2023-07-17T11:07:27.405+0000] {logging_mixin.py:150} INFO - [2023-07-17T11:07:27.405+0000] {dag.py:2742} INFO - Sync 1 DAGs
[2023-07-17T11:07:27.415+0000] {logging_mixin.py:150} INFO - [2023-07-17T11:07:27.415+0000] {dag.py:2763} INFO - Creating ORM DAG for latest_only
[2023-07-17T11:07:27.432+0000] {logging_mixin.py:150} INFO - [2023-07-17T11:07:27.432+0000] {dag.py:3508} INFO - Setting next_dagrun for latest_only to 2023-07-17T07:07:27.431855+00:00, run_after=2023-07-17T11:07:27.431855+00:00
[2023-07-17T11:07:27.454+0000] {processor.py:179} INFO - Processing /home/airflow/.local/lib/python3.7/site-packages/airflow/example_dags/example_latest_only.py took 0.654 seconds
[2023-07-17T11:08:39.649+0000] {processor.py:157} INFO - Started process (PID=33) to work on /home/airflow/.local/lib/python3.7/site-packages/airflow/example_dags/example_latest_only.py
[2023-07-17T11:08:39.679+0000] {processor.py:826} INFO - Processing file /home/airflow/.local/lib/python3.7/site-packages/airflow/example_dags/example_latest_only.py for tasks to queue
[2023-07-17T11:08:39.693+0000] {logging_mixin.py:150} INFO - [2023-07-17T11:08:39.692+0000] {dagbag.py:541} INFO - Filling up the DagBag from /home/airflow/.local/lib/python3.7/site-packages/airflow/example_dags/example_latest_only.py
[2023-07-17T11:08:39.863+0000] {processor.py:836} INFO - DAG(s) dict_keys(['latest_only']) retrieved from /home/airflow/.local/lib/python3.7/site-packages/airflow/example_dags/example_latest_only.py
[2023-07-17T11:08:40.313+0000] {logging_mixin.py:150} INFO - [2023-07-17T11:08:40.313+0000] {dag.py:2742} INFO - Sync 1 DAGs
[2023-07-17T11:08:40.342+0000] {logging_mixin.py:150} INFO - [2023-07-17T11:08:40.342+0000] {dag.py:3508} INFO - Setting next_dagrun for latest_only to 2023-07-17T07:08:40.342092+00:00, run_after=2023-07-17T11:08:40.342092+00:00
[2023-07-17T11:08:40.392+0000] {processor.py:179} INFO - Processing /home/airflow/.local/lib/python3.7/site-packages/airflow/example_dags/example_latest_only.py took 0.790 seconds
